Debugger listening on ws://0.0.0.0:8888/d9586991-64f4-4ea7-82b0-72b0d52c28a1
For help see https://nodejs.org/en/docs/inspector
{ Error: 
    CLIENT_RES_ERR
    There was a problem while invoking the chaincode
    Chaincode error, this is a wrapper around the responses

    Original stack:
    Error: make sure the chaincode person has been successfully instantiated and try again: chaincode person not found
    at self._endorserClient.processProposal (/home/blockchain/bTest/node_modules/fabric-client/lib/Peer.js:140:36)
    at Object.onReceiveStatus (/home/blockchain/bTest/node_modules/grpc/src/client_interceptors.js:1207:9)
    at InterceptingListener._callNext (/home/blockchain/bTest/node_modules/grpc/src/client_interceptors.js:568:42)
    at InterceptingListener.onReceiveStatus (/home/blockchain/bTest/node_modules/grpc/src/client_interceptors.js:618:8)
    at callback (/home/blockchain/bTest/node_modules/grpc/src/client_interceptors.js:845:24)
    
    at ClientResponseError.BaseError [as constructor] (/home/blockchain/bTest/node_modules/@worldsibu/convector-core-errors/src/base.error.ts:18:5)
    at new ClientResponseError (/home/blockchain/bTest/node_modules/@worldsibu/convector-core-errors/src/client.errors.ts:16:5)
    at FabricControllerAdapter.<anonymous> (/home/blockchain/bTest/node_modules/@worldsibu/convector-adapter-fabric/src/fabric.controller-adapter.ts:34:15)
    at step (/home/blockchain/bTest/node_modules/tslib/tslib.js:136:27)
    at Object.throw (/home/blockchain/bTest/node_modules/tslib/tslib.js:117:57)
    at rejected (/home/blockchain/bTest/node_modules/tslib/tslib.js:108:69)
    at <anonymous>
  code: 'CLIENT_RES_ERR',
  explanation: 'Chaincode error, this is a wrapper around the responses',
  description: 'There was a problem while invoking the chaincode',
  responses: 
   [ { error: [Object], response: [Object] },
     { error: [Object], response: [Object] } ],
  message: '\n    CLIENT_RES_ERR\n    There was a problem while invoking the chaincode\n    Chaincode error, this is a wrapper around the responses\n\n    Original stack:\n    Error: make sure the chaincode person has been successfully instantiated and try again: chaincode person not found\n    at self._endorserClient.processProposal (/home/blockchain/bTest/node_modules/fabric-client/lib/Peer.js:140:36)\n    at Object.onReceiveStatus (/home/blockchain/bTest/node_modules/grpc/src/client_interceptors.js:1207:9)\n    at InterceptingListener._callNext (/home/blockchain/bTest/node_modules/grpc/src/client_interceptors.js:568:42)\n    at InterceptingListener.onReceiveStatus (/home/blockchain/bTest/node_modules/grpc/src/client_interceptors.js:618:8)\n    at callback (/home/blockchain/bTest/node_modules/grpc/src/client_interceptors.js:845:24)\n    ' }
Debugger listening on ws://0.0.0.0:8888/f70f0bcc-cee0-4a56-96f3-0d3a7227629b
For help see https://nodejs.org/en/docs/inspector
Debugger listening on ws://0.0.0.0:8888/bebe1f6b-54b6-4fb7-a682-10d8bc64470b
For help see https://nodejs.org/en/docs/inspector
{ Error: 
    CLIENT_RES_ERR
    There was a problem while invoking the chaincode
    Chaincode error, this is a wrapper around the responses

    Original stack:
    Error: make sure the chaincode person has been successfully instantiated and try again: chaincode person not found
    at self._endorserClient.processProposal (/home/blockchain/bTest/node_modules/fabric-client/lib/Peer.js:140:36)
    at Object.onReceiveStatus (/home/blockchain/bTest/node_modules/grpc/src/client_interceptors.js:1207:9)
    at InterceptingListener._callNext (/home/blockchain/bTest/node_modules/grpc/src/client_interceptors.js:568:42)
    at InterceptingListener.onReceiveStatus (/home/blockchain/bTest/node_modules/grpc/src/client_interceptors.js:618:8)
    at callback (/home/blockchain/bTest/node_modules/grpc/src/client_interceptors.js:845:24)
    
    at ClientResponseError.BaseError [as constructor] (/home/blockchain/bTest/node_modules/@worldsibu/convector-core-errors/src/base.error.ts:18:5)
    at new ClientResponseError (/home/blockchain/bTest/node_modules/@worldsibu/convector-core-errors/src/client.errors.ts:16:5)
    at FabricControllerAdapter.<anonymous> (/home/blockchain/bTest/node_modules/@worldsibu/convector-adapter-fabric/src/fabric.controller-adapter.ts:34:15)
    at step (/home/blockchain/bTest/node_modules/tslib/tslib.js:136:27)
    at Object.throw (/home/blockchain/bTest/node_modules/tslib/tslib.js:117:57)
    at rejected (/home/blockchain/bTest/node_modules/tslib/tslib.js:108:69)
    at <anonymous>
  code: 'CLIENT_RES_ERR',
  explanation: 'Chaincode error, this is a wrapper around the responses',
  description: 'There was a problem while invoking the chaincode',
  responses: 
   [ { error: [Object], response: [Object] },
     { error: [Object], response: [Object] } ],
  message: '\n    CLIENT_RES_ERR\n    There was a problem while invoking the chaincode\n    Chaincode error, this is a wrapper around the responses\n\n    Original stack:\n    Error: make sure the chaincode person has been successfully instantiated and try again: chaincode person not found\n    at self._endorserClient.processProposal (/home/blockchain/bTest/node_modules/fabric-client/lib/Peer.js:140:36)\n    at Object.onReceiveStatus (/home/blockchain/bTest/node_modules/grpc/src/client_interceptors.js:1207:9)\n    at InterceptingListener._callNext (/home/blockchain/bTest/node_modules/grpc/src/client_interceptors.js:568:42)\n    at InterceptingListener.onReceiveStatus (/home/blockchain/bTest/node_modules/grpc/src/client_interceptors.js:618:8)\n    at callback (/home/blockchain/bTest/node_modules/grpc/src/client_interceptors.js:845:24)\n    ' }
{ Error: 
    CLIENT_RES_ERR
    There was a problem while invoking the chaincode
    Chaincode error, this is a wrapper around the responses

    Original stack:
    Error: make sure the chaincode person has been successfully instantiated and try again: chaincode person not found
    at self._endorserClient.processProposal (/home/blockchain/bTest/node_modules/fabric-client/lib/Peer.js:140:36)
    at Object.onReceiveStatus (/home/blockchain/bTest/node_modules/grpc/src/client_interceptors.js:1207:9)
    at InterceptingListener._callNext (/home/blockchain/bTest/node_modules/grpc/src/client_interceptors.js:568:42)
    at InterceptingListener.onReceiveStatus (/home/blockchain/bTest/node_modules/grpc/src/client_interceptors.js:618:8)
    at callback (/home/blockchain/bTest/node_modules/grpc/src/client_interceptors.js:845:24)
    
    at ClientResponseError.BaseError [as constructor] (/home/blockchain/bTest/node_modules/@worldsibu/convector-core-errors/src/base.error.ts:18:5)
    at new ClientResponseError (/home/blockchain/bTest/node_modules/@worldsibu/convector-core-errors/src/client.errors.ts:16:5)
    at FabricControllerAdapter.<anonymous> (/home/blockchain/bTest/node_modules/@worldsibu/convector-adapter-fabric/src/fabric.controller-adapter.ts:34:15)
    at step (/home/blockchain/bTest/node_modules/tslib/tslib.js:136:27)
    at Object.throw (/home/blockchain/bTest/node_modules/tslib/tslib.js:117:57)
    at rejected (/home/blockchain/bTest/node_modules/tslib/tslib.js:108:69)
    at <anonymous>
  code: 'CLIENT_RES_ERR',
  explanation: 'Chaincode error, this is a wrapper around the responses',
  description: 'There was a problem while invoking the chaincode',
  responses: 
   [ { error: [Object], response: [Object] },
     { error: [Object], response: [Object] } ],
  message: '\n    CLIENT_RES_ERR\n    There was a problem while invoking the chaincode\n    Chaincode error, this is a wrapper around the responses\n\n    Original stack:\n    Error: make sure the chaincode person has been successfully instantiated and try again: chaincode person not found\n    at self._endorserClient.processProposal (/home/blockchain/bTest/node_modules/fabric-client/lib/Peer.js:140:36)\n    at Object.onReceiveStatus (/home/blockchain/bTest/node_modules/grpc/src/client_interceptors.js:1207:9)\n    at InterceptingListener._callNext (/home/blockchain/bTest/node_modules/grpc/src/client_interceptors.js:568:42)\n    at InterceptingListener.onReceiveStatus (/home/blockchain/bTest/node_modules/grpc/src/client_interceptors.js:618:8)\n    at callback (/home/blockchain/bTest/node_modules/grpc/src/client_interceptors.js:845:24)\n    ' }
{ Error: 
    CLIENT_RES_ERR
    There was a problem while invoking the chaincode
    Chaincode error, this is a wrapper around the responses

    Original stack:
    Error: make sure the chaincode person has been successfully instantiated and try again: chaincode person not found
    at self._endorserClient.processProposal (/home/blockchain/bTest/node_modules/fabric-client/lib/Peer.js:140:36)
    at Object.onReceiveStatus (/home/blockchain/bTest/node_modules/grpc/src/client_interceptors.js:1207:9)
    at InterceptingListener._callNext (/home/blockchain/bTest/node_modules/grpc/src/client_interceptors.js:568:42)
    at InterceptingListener.onReceiveStatus (/home/blockchain/bTest/node_modules/grpc/src/client_interceptors.js:618:8)
    at callback (/home/blockchain/bTest/node_modules/grpc/src/client_interceptors.js:845:24)
    
    at ClientResponseError.BaseError [as constructor] (/home/blockchain/bTest/node_modules/@worldsibu/convector-core-errors/src/base.error.ts:18:5)
    at new ClientResponseError (/home/blockchain/bTest/node_modules/@worldsibu/convector-core-errors/src/client.errors.ts:16:5)
    at FabricControllerAdapter.<anonymous> (/home/blockchain/bTest/node_modules/@worldsibu/convector-adapter-fabric/src/fabric.controller-adapter.ts:34:15)
    at step (/home/blockchain/bTest/node_modules/tslib/tslib.js:136:27)
    at Object.throw (/home/blockchain/bTest/node_modules/tslib/tslib.js:117:57)
    at rejected (/home/blockchain/bTest/node_modules/tslib/tslib.js:108:69)
    at <anonymous>
  code: 'CLIENT_RES_ERR',
  explanation: 'Chaincode error, this is a wrapper around the responses',
  description: 'There was a problem while invoking the chaincode',
  responses: 
   [ { error: [Object], response: [Object] },
     { error: [Object], response: [Object] } ],
  message: '\n    CLIENT_RES_ERR\n    There was a problem while invoking the chaincode\n    Chaincode error, this is a wrapper around the responses\n\n    Original stack:\n    Error: make sure the chaincode person has been successfully instantiated and try again: chaincode person not found\n    at self._endorserClient.processProposal (/home/blockchain/bTest/node_modules/fabric-client/lib/Peer.js:140:36)\n    at Object.onReceiveStatus (/home/blockchain/bTest/node_modules/grpc/src/client_interceptors.js:1207:9)\n    at InterceptingListener._callNext (/home/blockchain/bTest/node_modules/grpc/src/client_interceptors.js:568:42)\n    at InterceptingListener.onReceiveStatus (/home/blockchain/bTest/node_modules/grpc/src/client_interceptors.js:618:8)\n    at callback (/home/blockchain/bTest/node_modules/grpc/src/client_interceptors.js:845:24)\n    ' }
Debugger listening on ws://0.0.0.0:8888/407925cb-3254-499e-b5cc-04c204097305
For help see https://nodejs.org/en/docs/inspector
{ Error: 
    CLIENT_RES_ERR
    There was a problem while invoking the chaincode
    Chaincode error, this is a wrapper around the responses

    Original stack:
    Error: make sure the chaincode person has been successfully instantiated and try again: chaincode person not found
    at self._endorserClient.processProposal (/home/blockchain/bTest/node_modules/fabric-client/lib/Peer.js:140:36)
    at Object.onReceiveStatus (/home/blockchain/bTest/node_modules/grpc/src/client_interceptors.js:1207:9)
    at InterceptingListener._callNext (/home/blockchain/bTest/node_modules/grpc/src/client_interceptors.js:568:42)
    at InterceptingListener.onReceiveStatus (/home/blockchain/bTest/node_modules/grpc/src/client_interceptors.js:618:8)
    at callback (/home/blockchain/bTest/node_modules/grpc/src/client_interceptors.js:845:24)
    
    at ClientResponseError.BaseError [as constructor] (/home/blockchain/bTest/node_modules/@worldsibu/convector-core-errors/src/base.error.ts:18:5)
    at new ClientResponseError (/home/blockchain/bTest/node_modules/@worldsibu/convector-core-errors/src/client.errors.ts:16:5)
    at FabricControllerAdapter.<anonymous> (/home/blockchain/bTest/node_modules/@worldsibu/convector-adapter-fabric/src/fabric.controller-adapter.ts:34:15)
    at step (/home/blockchain/bTest/node_modules/tslib/tslib.js:136:27)
    at Object.throw (/home/blockchain/bTest/node_modules/tslib/tslib.js:117:57)
    at rejected (/home/blockchain/bTest/node_modules/tslib/tslib.js:108:69)
    at <anonymous>
  code: 'CLIENT_RES_ERR',
  explanation: 'Chaincode error, this is a wrapper around the responses',
  description: 'There was a problem while invoking the chaincode',
  responses: 
   [ { error: [Object], response: [Object] },
     { error: [Object], response: [Object] } ],
  message: '\n    CLIENT_RES_ERR\n    There was a problem while invoking the chaincode\n    Chaincode error, this is a wrapper around the responses\n\n    Original stack:\n    Error: make sure the chaincode person has been successfully instantiated and try again: chaincode person not found\n    at self._endorserClient.processProposal (/home/blockchain/bTest/node_modules/fabric-client/lib/Peer.js:140:36)\n    at Object.onReceiveStatus (/home/blockchain/bTest/node_modules/grpc/src/client_interceptors.js:1207:9)\n    at InterceptingListener._callNext (/home/blockchain/bTest/node_modules/grpc/src/client_interceptors.js:568:42)\n    at InterceptingListener.onReceiveStatus (/home/blockchain/bTest/node_modules/grpc/src/client_interceptors.js:618:8)\n    at callback (/home/blockchain/bTest/node_modules/grpc/src/client_interceptors.js:845:24)\n    ' }
Debugger listening on ws://0.0.0.0:8888/92ab8129-aa1e-4cb5-8594-3dbe4cfdfbf2
For help see https://nodejs.org/en/docs/inspector
{ Error: 
    CLIENT_RES_ERR
    There was a problem while invoking the chaincode
    Chaincode error, this is a wrapper around the responses

    Original stack:
    Error: make sure the chaincode person has been successfully instantiated and try again: chaincode person not found
    at self._endorserClient.processProposal (/home/blockchain/bTest/node_modules/fabric-client/lib/Peer.js:140:36)
    at Object.onReceiveStatus (/home/blockchain/bTest/node_modules/grpc/src/client_interceptors.js:1207:9)
    at InterceptingListener._callNext (/home/blockchain/bTest/node_modules/grpc/src/client_interceptors.js:568:42)
    at InterceptingListener.onReceiveStatus (/home/blockchain/bTest/node_modules/grpc/src/client_interceptors.js:618:8)
    at callback (/home/blockchain/bTest/node_modules/grpc/src/client_interceptors.js:845:24)
    
    at ClientResponseError.BaseError [as constructor] (/home/blockchain/bTest/node_modules/@worldsibu/convector-core-errors/src/base.error.ts:18:5)
    at new ClientResponseError (/home/blockchain/bTest/node_modules/@worldsibu/convector-core-errors/src/client.errors.ts:16:5)
    at FabricControllerAdapter.<anonymous> (/home/blockchain/bTest/node_modules/@worldsibu/convector-adapter-fabric/src/fabric.controller-adapter.ts:34:15)
    at step (/home/blockchain/bTest/node_modules/tslib/tslib.js:136:27)
    at Object.throw (/home/blockchain/bTest/node_modules/tslib/tslib.js:117:57)
    at rejected (/home/blockchain/bTest/node_modules/tslib/tslib.js:108:69)
    at <anonymous>
  code: 'CLIENT_RES_ERR',
  explanation: 'Chaincode error, this is a wrapper around the responses',
  description: 'There was a problem while invoking the chaincode',
  responses: 
   [ { error: [Object], response: [Object] },
     { error: [Object], response: [Object] } ],
  message: '\n    CLIENT_RES_ERR\n    There was a problem while invoking the chaincode\n    Chaincode error, this is a wrapper around the responses\n\n    Original stack:\n    Error: make sure the chaincode person has been successfully instantiated and try again: chaincode person not found\n    at self._endorserClient.processProposal (/home/blockchain/bTest/node_modules/fabric-client/lib/Peer.js:140:36)\n    at Object.onReceiveStatus (/home/blockchain/bTest/node_modules/grpc/src/client_interceptors.js:1207:9)\n    at InterceptingListener._callNext (/home/blockchain/bTest/node_modules/grpc/src/client_interceptors.js:568:42)\n    at InterceptingListener.onReceiveStatus (/home/blockchain/bTest/node_modules/grpc/src/client_interceptors.js:618:8)\n    at callback (/home/blockchain/bTest/node_modules/grpc/src/client_interceptors.js:845:24)\n    ' }
Debugger listening on ws://0.0.0.0:8888/17afa992-ff8f-4213-b19b-7e10af6a19e4
For help see https://nodejs.org/en/docs/inspector
{ Error: 
    CLIENT_RES_ERR
    There was a problem while invoking the chaincode
    Chaincode error, this is a wrapper around the responses

    Original stack:
    Error: make sure the chaincode person has been successfully instantiated and try again: chaincode person not found
    at self._endorserClient.processProposal (/home/blockchain/bTest/node_modules/fabric-client/lib/Peer.js:140:36)
    at Object.onReceiveStatus (/home/blockchain/bTest/node_modules/grpc/src/client_interceptors.js:1207:9)
    at InterceptingListener._callNext (/home/blockchain/bTest/node_modules/grpc/src/client_interceptors.js:568:42)
    at InterceptingListener.onReceiveStatus (/home/blockchain/bTest/node_modules/grpc/src/client_interceptors.js:618:8)
    at callback (/home/blockchain/bTest/node_modules/grpc/src/client_interceptors.js:845:24)
    
    at ClientResponseError.BaseError [as constructor] (/home/blockchain/bTest/node_modules/@worldsibu/convector-core-errors/src/base.error.ts:18:5)
    at new ClientResponseError (/home/blockchain/bTest/node_modules/@worldsibu/convector-core-errors/src/client.errors.ts:16:5)
    at FabricControllerAdapter.<anonymous> (/home/blockchain/bTest/node_modules/@worldsibu/convector-adapter-fabric/src/fabric.controller-adapter.ts:34:15)
    at step (/home/blockchain/bTest/node_modules/tslib/tslib.js:136:27)
    at Object.throw (/home/blockchain/bTest/node_modules/tslib/tslib.js:117:57)
    at rejected (/home/blockchain/bTest/node_modules/tslib/tslib.js:108:69)
    at <anonymous>
  code: 'CLIENT_RES_ERR',
  explanation: 'Chaincode error, this is a wrapper around the responses',
  description: 'There was a problem while invoking the chaincode',
  responses: 
   [ { error: [Object], response: [Object] },
     { error: [Object], response: [Object] } ],
  message: '\n    CLIENT_RES_ERR\n    There was a problem while invoking the chaincode\n    Chaincode error, this is a wrapper around the responses\n\n    Original stack:\n    Error: make sure the chaincode person has been successfully instantiated and try again: chaincode person not found\n    at self._endorserClient.processProposal (/home/blockchain/bTest/node_modules/fabric-client/lib/Peer.js:140:36)\n    at Object.onReceiveStatus (/home/blockchain/bTest/node_modules/grpc/src/client_interceptors.js:1207:9)\n    at InterceptingListener._callNext (/home/blockchain/bTest/node_modules/grpc/src/client_interceptors.js:568:42)\n    at InterceptingListener.onReceiveStatus (/home/blockchain/bTest/node_modules/grpc/src/client_interceptors.js:618:8)\n    at callback (/home/blockchain/bTest/node_modules/grpc/src/client_interceptors.js:845:24)\n    ' }
{ Error: 
    CLIENT_RES_ERR
    There was a problem while invoking the chaincode
    Chaincode error, this is a wrapper around the responses

    Original stack:
    Error: make sure the chaincode person has been successfully instantiated and try again: chaincode person not found
    at self._endorserClient.processProposal (/home/blockchain/bTest/node_modules/fabric-client/lib/Peer.js:140:36)
    at Object.onReceiveStatus (/home/blockchain/bTest/node_modules/grpc/src/client_interceptors.js:1207:9)
    at InterceptingListener._callNext (/home/blockchain/bTest/node_modules/grpc/src/client_interceptors.js:568:42)
    at InterceptingListener.onReceiveStatus (/home/blockchain/bTest/node_modules/grpc/src/client_interceptors.js:618:8)
    at callback (/home/blockchain/bTest/node_modules/grpc/src/client_interceptors.js:845:24)
    
    at ClientResponseError.BaseError [as constructor] (/home/blockchain/bTest/node_modules/@worldsibu/convector-core-errors/src/base.error.ts:18:5)
    at new ClientResponseError (/home/blockchain/bTest/node_modules/@worldsibu/convector-core-errors/src/client.errors.ts:16:5)
    at FabricControllerAdapter.<anonymous> (/home/blockchain/bTest/node_modules/@worldsibu/convector-adapter-fabric/src/fabric.controller-adapter.ts:34:15)
    at step (/home/blockchain/bTest/node_modules/tslib/tslib.js:136:27)
    at Object.throw (/home/blockchain/bTest/node_modules/tslib/tslib.js:117:57)
    at rejected (/home/blockchain/bTest/node_modules/tslib/tslib.js:108:69)
    at <anonymous>
  code: 'CLIENT_RES_ERR',
  explanation: 'Chaincode error, this is a wrapper around the responses',
  description: 'There was a problem while invoking the chaincode',
  responses: 
   [ { error: [Object], response: [Object] },
     { error: [Object], response: [Object] } ],
  message: '\n    CLIENT_RES_ERR\n    There was a problem while invoking the chaincode\n    Chaincode error, this is a wrapper around the responses\n\n    Original stack:\n    Error: make sure the chaincode person has been successfully instantiated and try again: chaincode person not found\n    at self._endorserClient.processProposal (/home/blockchain/bTest/node_modules/fabric-client/lib/Peer.js:140:36)\n    at Object.onReceiveStatus (/home/blockchain/bTest/node_modules/grpc/src/client_interceptors.js:1207:9)\n    at InterceptingListener._callNext (/home/blockchain/bTest/node_modules/grpc/src/client_interceptors.js:568:42)\n    at InterceptingListener.onReceiveStatus (/home/blockchain/bTest/node_modules/grpc/src/client_interceptors.js:618:8)\n    at callback (/home/blockchain/bTest/node_modules/grpc/src/client_interceptors.js:845:24)\n    ' }
Debugger listening on ws://0.0.0.0:8888/4dca70f7-a34a-4fb5-bc1b-a2ae7ca6181d
For help see https://nodejs.org/en/docs/inspector
Debugger listening on ws://0.0.0.0:8888/e90d0fdd-3be3-458b-97a7-8dedf038cf39
For help see https://nodejs.org/en/docs/inspector
Debugger listening on ws://0.0.0.0:8888/13a5f61c-02c9-4067-97a9-9c5e53d16039
For help see https://nodejs.org/en/docs/inspector
Debugger listening on ws://0.0.0.0:8888/bb95d56c-7f4a-472d-8e0d-fe93cf6579a0
For help see https://nodejs.org/en/docs/inspector
Debugger listening on ws://0.0.0.0:8888/1d9f21d7-dcad-4c49-a3dc-2666cb4d921d
For help see https://nodejs.org/en/docs/inspector
Debugger listening on ws://0.0.0.0:8888/f60e986a-aa0c-40f0-af7e-31b98ae42073
For help see https://nodejs.org/en/docs/inspector
Debugger listening on ws://0.0.0.0:8888/b15a6e60-fe04-437a-bb72-42779b978432
For help see https://nodejs.org/en/docs/inspector
Debugger listening on ws://0.0.0.0:8888/5389bdfd-debe-4c80-8737-788ad9d028fc
For help see https://nodejs.org/en/docs/inspector
Debugger listening on ws://0.0.0.0:8888/5b970e22-fa50-41c0-be75-a3373eda9782
For help see https://nodejs.org/en/docs/inspector
Debugger listening on ws://0.0.0.0:8888/56e0f60a-cc4b-4e11-b280-97ad04ad5937
For help see https://nodejs.org/en/docs/inspector
Debugger listening on ws://0.0.0.0:8888/758315e6-51dd-4737-8312-0a383ea6c75b
For help see https://nodejs.org/en/docs/inspector
module.js:549
    throw err;
    ^

Error: Cannot find module '/home/blockchain/bTest/node_modules/pm2/lib/ProcessContainerFork.js'
    at Function.Module._resolveFilename (module.js:547:15)
    at Function.Module._load (module.js:474:25)
    at Function.Module.runMain (module.js:693:10)
    at startup (bootstrap_node.js:191:16)
    at bootstrap_node.js:612:3
Debugger listening on ws://0.0.0.0:8888/aee77178-6e10-4a84-82ae-bedf569466ac
For help see https://nodejs.org/en/docs/inspector
module.js:549
    throw err;
    ^

Error: Cannot find module '/home/blockchain/bTest/node_modules/pm2/lib/ProcessContainerFork.js'
    at Function.Module._resolveFilename (module.js:547:15)
    at Function.Module._load (module.js:474:25)
    at Function.Module.runMain (module.js:693:10)
    at startup (bootstrap_node.js:191:16)
    at bootstrap_node.js:612:3
Debugger listening on ws://0.0.0.0:8888/3765ff9e-380b-46ba-9ce9-a4caefcd05da
For help see https://nodejs.org/en/docs/inspector
module.js:549
    throw err;
    ^

Error: Cannot find module '/home/blockchain/bTest/node_modules/pm2/lib/ProcessContainerFork.js'
    at Function.Module._resolveFilename (module.js:547:15)
    at Function.Module._load (module.js:474:25)
    at Function.Module.runMain (module.js:693:10)
    at startup (bootstrap_node.js:191:16)
    at bootstrap_node.js:612:3
Debugger listening on ws://0.0.0.0:8888/3d70ce61-6530-4b74-97a0-32a4744a6159
For help see https://nodejs.org/en/docs/inspector
module.js:549
    throw err;
    ^

Error: Cannot find module '/home/blockchain/bTest/node_modules/pm2/lib/ProcessContainerFork.js'
    at Function.Module._resolveFilename (module.js:547:15)
    at Function.Module._load (module.js:474:25)
    at Function.Module.runMain (module.js:693:10)
    at startup (bootstrap_node.js:191:16)
    at bootstrap_node.js:612:3
Debugger listening on ws://0.0.0.0:8888/7a6ae35a-2317-4a82-b852-1f326ef059de
For help see https://nodejs.org/en/docs/inspector
module.js:549
    throw err;
    ^

Error: Cannot find module '/home/blockchain/bTest/node_modules/pm2/lib/ProcessContainerFork.js'
    at Function.Module._resolveFilename (module.js:547:15)
    at Function.Module._load (module.js:474:25)
    at Function.Module.runMain (module.js:693:10)
    at startup (bootstrap_node.js:191:16)
    at bootstrap_node.js:612:3
Debugger listening on ws://0.0.0.0:8888/15e23be7-11f7-4e14-a597-bba75993307c
For help see https://nodejs.org/en/docs/inspector
module.js:549
    throw err;
    ^

Error: Cannot find module '/home/blockchain/bTest/node_modules/pm2/lib/ProcessContainerFork.js'
    at Function.Module._resolveFilename (module.js:547:15)
    at Function.Module._load (module.js:474:25)
    at Function.Module.runMain (module.js:693:10)
    at startup (bootstrap_node.js:191:16)
    at bootstrap_node.js:612:3
Debugger listening on ws://0.0.0.0:8888/396cfb23-3f5f-403f-b22a-995e11c3a606
For help see https://nodejs.org/en/docs/inspector
module.js:549
    throw err;
    ^

Error: Cannot find module '/home/blockchain/bTest/node_modules/pm2/lib/ProcessContainerFork.js'
    at Function.Module._resolveFilename (module.js:547:15)
    at Function.Module._load (module.js:474:25)
    at Function.Module.runMain (module.js:693:10)
    at startup (bootstrap_node.js:191:16)
    at bootstrap_node.js:612:3
Debugger listening on ws://0.0.0.0:8888/c8304bdf-3468-4ad1-a12a-88a1d76a5e59
For help see https://nodejs.org/en/docs/inspector
module.js:549
    throw err;
    ^

Error: Cannot find module '/home/blockchain/bTest/node_modules/pm2/lib/ProcessContainerFork.js'
    at Function.Module._resolveFilename (module.js:547:15)
    at Function.Module._load (module.js:474:25)
    at Function.Module.runMain (module.js:693:10)
    at startup (bootstrap_node.js:191:16)
    at bootstrap_node.js:612:3
Debugger listening on ws://0.0.0.0:8888/d7b4344c-234e-463d-9176-4adefc2a1ff9
For help see https://nodejs.org/en/docs/inspector
module.js:549
    throw err;
    ^

Error: Cannot find module '/home/blockchain/bTest/node_modules/pm2/lib/ProcessContainerFork.js'
    at Function.Module._resolveFilename (module.js:547:15)
    at Function.Module._load (module.js:474:25)
    at Function.Module.runMain (module.js:693:10)
    at startup (bootstrap_node.js:191:16)
    at bootstrap_node.js:612:3
Debugger listening on ws://0.0.0.0:8888/1c1dee75-e0b7-4094-b5d9-55ff49f1f7e3
For help see https://nodejs.org/en/docs/inspector
module.js:549
    throw err;
    ^

Error: Cannot find module '/home/blockchain/bTest/node_modules/pm2/lib/ProcessContainerFork.js'
    at Function.Module._resolveFilename (module.js:547:15)
    at Function.Module._load (module.js:474:25)
    at Function.Module.runMain (module.js:693:10)
    at startup (bootstrap_node.js:191:16)
    at bootstrap_node.js:612:3
Debugger listening on ws://0.0.0.0:8888/f73cad82-a1ad-4a47-a2be-dd4638a76329
For help see https://nodejs.org/en/docs/inspector
module.js:549
    throw err;
    ^

Error: Cannot find module '/home/blockchain/bTest/node_modules/pm2/lib/ProcessContainerFork.js'
    at Function.Module._resolveFilename (module.js:547:15)
    at Function.Module._load (module.js:474:25)
    at Function.Module.runMain (module.js:693:10)
    at startup (bootstrap_node.js:191:16)
    at bootstrap_node.js:612:3
Debugger listening on ws://0.0.0.0:8888/db3a4a90-cf7e-444c-9a41-1284bbf545cb
For help see https://nodejs.org/en/docs/inspector
module.js:549
    throw err;
    ^

Error: Cannot find module '/home/blockchain/bTest/node_modules/pm2/lib/ProcessContainerFork.js'
    at Function.Module._resolveFilename (module.js:547:15)
    at Function.Module._load (module.js:474:25)
    at Function.Module.runMain (module.js:693:10)
    at startup (bootstrap_node.js:191:16)
    at bootstrap_node.js:612:3
Debugger listening on ws://0.0.0.0:8888/b34ca63e-1891-469a-933a-5d125fc5e2bc
For help see https://nodejs.org/en/docs/inspector
module.js:549
    throw err;
    ^

Error: Cannot find module '/home/blockchain/bTest/node_modules/pm2/lib/ProcessContainerFork.js'
    at Function.Module._resolveFilename (module.js:547:15)
    at Function.Module._load (module.js:474:25)
    at Function.Module.runMain (module.js:693:10)
    at startup (bootstrap_node.js:191:16)
    at bootstrap_node.js:612:3
Debugger listening on ws://0.0.0.0:8888/0ff8f7ae-e5d6-4f30-b2b0-ba4ee7ba2b40
For help see https://nodejs.org/en/docs/inspector
module.js:549
    throw err;
    ^

Error: Cannot find module '/home/blockchain/bTest/node_modules/pm2/lib/ProcessContainerFork.js'
    at Function.Module._resolveFilename (module.js:547:15)
    at Function.Module._load (module.js:474:25)
    at Function.Module.runMain (module.js:693:10)
    at startup (bootstrap_node.js:191:16)
    at bootstrap_node.js:612:3
Debugger listening on ws://0.0.0.0:8888/5c34e475-e4c0-42a6-8d2f-ab50f4544e0f
For help see https://nodejs.org/en/docs/inspector
module.js:549
    throw err;
    ^

Error: Cannot find module '/home/blockchain/bTest/node_modules/pm2/lib/ProcessContainerFork.js'
    at Function.Module._resolveFilename (module.js:547:15)
    at Function.Module._load (module.js:474:25)
    at Function.Module.runMain (module.js:693:10)
    at startup (bootstrap_node.js:191:16)
    at bootstrap_node.js:612:3
Debugger listening on ws://0.0.0.0:8888/fa6ea2af-f24b-488a-9a0e-e66dc97888d1
For help see https://nodejs.org/en/docs/inspector
module.js:549
    throw err;
    ^

Error: Cannot find module '/home/blockchain/bTest/node_modules/pm2/lib/ProcessContainerFork.js'
    at Function.Module._resolveFilename (module.js:547:15)
    at Function.Module._load (module.js:474:25)
    at Function.Module.runMain (module.js:693:10)
    at startup (bootstrap_node.js:191:16)
    at bootstrap_node.js:612:3
